<?xml version="1.0"?>
<robot name="spec_based_quadruped">

    <link name="base_link">
        <visual>
            <geometry>
                <box size="0.49 0.26 0.096"/> 
            </geometry>
            <material name="blue"/>
        </visual>
        <collision>
            <geometry>
                <box size="0.49 0.26 0.096"/>
            </geometry>
        </collision>
        <inertial>
            <origin xyz="0 0 0" rpy="0 0 0"/> 
            <mass value="5.0"/> 
            <inertia ixx="0.1" ixy="0.0" ixz="0.0" iyy="0.1" iyz="0.0" izz="0.1"/> 
        </inertial>
    </link>

    <joint name="FR_hip_joint" type="revolute">
        <parent link="base_link"/>
        <child link="FR_hip_link"/>
        <origin xyz="0.195 -0.145 0" rpy="0 0 0"/> 
        <axis xyz="1 0 0"/> 
        <limit lower="-0.5" upper="0.5" effort="10" velocity="10"/> 
    </joint>

    <link name="FR_hip_link">
        <visual>
            <geometry>
                <box size="0.05 0.05 0.05"/>
            </geometry>
            <material name="green"/>
        </visual>
        <collision>
            <geometry>
                <box size="0.05 0.05 0.05"/>
            </geometry>
        </collision>
        <inertial>
            <origin xyz="0 0 0" rpy="0 0 0"/>
            <mass value="0.1"/> 
            <inertia ixx="0.001" ixy="0.0" ixz="0.0" iyy="0.001" iyz="0.0" izz="0.001"/>
        </inertial>
    </link>

    <joint name="FR_thigh_joint" type="revolute">
        <parent link="FR_hip_link"/>
        <child link="FR_thigh_link"/>
        <origin xyz="0 -0.025 0" rpy="0 0 0"/> 
        <axis xyz="0 1 0"/> 
        <limit lower="-1.5" upper="1.5" effort="10" velocity="10"/>
    </joint>

    <link name="FR_thigh_link">
        <visual>
            <geometry>
                <cylinder length="0.145" radius="0.02"/>
            </geometry>
            <origin xyz="0 0 -0.0725" rpy="0 0 0"/> 
            <material name="red"/>
        </visual>
        <collision>
            <geometry>
                <cylinder length="0.145" radius="0.02"/>
            </geometry>
            <origin xyz="0 0 -0.0725" rpy="0 0 0"/> 
        </collision>
        <inertial>
            <origin xyz="0 0 -0.0725" rpy="0 0 0"/>
            <mass value="0.075"/> 
            <inertia ixx="0.001" ixy="0.0" ixz="0.0" iyy="0.001" iyz="0.0" izz="0.001"/>
        </inertial>
    </link>

    <joint name="FR_shank_joint" type="revolute">
        <parent link="FR_thigh_link"/>
        <child link="FR_shank_link"/>
        <origin xyz="0 0 -0.145" rpy="0 0 0"/> 
        <axis xyz="0 1 0"/> 
        <limit lower="-2.5" upper="0" effort="10" velocity="10"/> 
    </joint>

    <link name="FR_shank_link">
        <visual>
            <geometry>
                <cylinder length="0.145" radius="0.02"/>
            </geometry>
            <origin xyz="0 0 -0.0725" rpy="0 0 0"/> 
            <material name="yellow"/>
        </visual>
        <collision>
            <geometry>
                <cylinder length="0.145" radius="0.02"/>
            </geometry>
            <origin xyz="0 0 -0.0725" rpy="0 0 0"/>
        </collision>
        <inertial>
            <origin xyz="0 0 -0.0725" rpy="0 0 0"/>
            <mass value="0.075"/> 
            <inertia ixx="0.001" ixy="0.0" ixz="0.0" iyy="0.001" iyz="0.0" izz="0.001"/>
        </inertial>
    </link>

    <joint name="FR_foot_joint" type="fixed"> 
        <parent link="FR_shank_link"/>
        <child link="FR_foot_link"/>
        <origin xyz="0 0 -0.145" rpy="0 0 0"/> </joint>

    <link name="FR_foot_link">
        <visual>
            <geometry>
                <sphere radius="0.02"/> 
            </geometry>
            <material name="black"/>
        </visual>
        <collision>
            <geometry>
                <sphere radius="0.02"/>
            </geometry>
            <contact_coefficients kd="100.0" kp="1000.0" mu="0.8"/> 
        </collision>
        <inertial>
            <origin xyz="0 0 0" rpy="0 0 0"/>
            <mass value="0.01"/> 
            <inertia ixx="0.0001" ixy="0.0" ixz="0.0" iyy="0.0001" iyz="0.0" izz="0.0001"/>
        </inertial>
    </link>

    <joint name="FL_hip_joint" type="revolute">
        <parent link="base_link"/>
        <child link="FL_hip_link"/>
        <origin xyz="0.195 0.145 0" rpy="0 0 0"/> 
        <axis xyz="1 0 0"/> 
        <limit lower="-0.5" upper="0.5" effort="10" velocity="10"/> 
    </joint>

    <link name="FL_hip_link">
        <visual>
            <geometry>
                <box size="0.05 0.05 0.05"/>
            </geometry>
            <material name="green"/>
        </visual>
        <collision>
            <geometry>
                <box size="0.05 0.05 0.05"/>
            </geometry>
        </collision>
        <inertial>
            <origin xyz="0 0 0" rpy="0 0 0"/>
            <mass value="0.1"/> 
            <inertia ixx="0.001" ixy="0.0" ixz="0.0" iyy="0.001" iyz="0.0" izz="0.001"/>
        </inertial>
    </link>

    <joint name="FL_thigh_joint" type="revolute">
        <parent link="FL_hip_link"/>
        <child link="FL_thigh_link"/>
        <origin xyz="0 0.025 0" rpy="0 0 0"/> 
        <axis xyz="0 1 0"/> 
        <limit lower="-1.5" upper="1.5" effort="10" velocity="10"/>
    </joint>

    <link name="FL_thigh_link">
        <visual>
            <geometry>
                <cylinder length="0.145" radius="0.02"/>
            </geometry>
            <origin xyz="0 0 -0.0725" rpy="0 0 0"/> 
            <material name="red"/>
        </visual>
        <collision>
            <geometry>
                <cylinder length="0.145" radius="0.02"/>
            </geometry>
            <origin xyz="0 0 -0.0725" rpy="0 0 0"/> 
        </collision>
        <inertial>
            <origin xyz="0 0 -0.0725" rpy="0 0 0"/>
            <mass value="0.075"/> 
            <inertia ixx="0.001" ixy="0.0" ixz="0.0" iyy="0.001" iyz="0.0" izz="0.001"/>
        </inertial>
    </link>

    <joint name="FL_shank_joint" type="revolute">
        <parent link="FL_thigh_link"/>
        <child link="FL_shank_link"/>
        <origin xyz="0 0 -0.145" rpy="0 0 0"/> 
        <axis xyz="0 1 0"/> 
        <limit lower="-2.5" upper="0" effort="10" velocity="10"/> 
    </joint>

    <link name="FL_shank_link">
        <visual>
            <geometry>
                <cylinder length="0.145" radius="0.02"/>
            </geometry>
            <origin xyz="0 0 -0.0725" rpy="0 0 0"/> 
            <material name="yellow"/>
        </visual>
        <collision>
            <geometry>
                <cylinder length="0.145" radius="0.02"/>
            </geometry>
            <origin xyz="0 0 -0.0725" rpy="0 0 0"/>
        </collision>
        <inertial>
            <origin xyz="0 0 -0.0725" rpy="0 0 0"/>
            <mass value="0.075"/> 
            <inertia ixx="0.001" ixy="0.0" ixz="0.0" iyy="0.001" iyz="0.0" izz="0.001"/>
        </inertial>
    </link>

    <joint name="FL_foot_joint" type="fixed"> 
        <parent link="FL_shank_link"/>
        <child link="FL_foot_link"/>
        <origin xyz="0 0 -0.145" rpy="0 0 0"/> 
    </joint>

    <link name="FL_foot_link">
        <visual>
            <geometry>
                <sphere radius="0.02"/> 
            </geometry>
            <material name="black"/>
        </visual>
        <collision>
            <geometry>
                <sphere radius="0.02"/>
            </geometry>
            <contact_coefficients kd="100.0" kp="1000.0" mu="0.8"/> 
        </collision>
        <inertial>
            <origin xyz="0 0 0" rpy="0 0 0"/>
            <mass value="0.01"/> 
            <inertia ixx="0.0001" ixy="0.0" ixz="0.0" iyy="0.0001" iyz="0.0" izz="0.0001"/>
        </inertial>
    </link>

    <joint name="RR_hip_joint" type="revolute">
        <parent link="base_link"/>
        <child link="RR_hip_link"/>
        <origin xyz="-0.195 -0.145 0" rpy="0 0 0"/> 
        <axis xyz="1 0 0"/> 
        <limit lower="-0.5" upper="0.5" effort="10" velocity="10"/> 
    </joint>

    <link name="RR_hip_link">
        <visual>
            <geometry>
                <box size="0.05 0.05 0.05"/>
            </geometry>
            <material name="green"/>
        </visual>
        <collision>
            <geometry>
                <box size="0.05 0.05 0.05"/>
            </geometry>
        </collision>
        <inertial>
            <origin xyz="0 0 0" rpy="0 0 0"/>
            <mass value="0.1"/> 
            <inertia ixx="0.001" ixy="0.0" ixz="0.0" iyy="0.001" iyz="0.0" izz="0.001"/>
        </inertial>
    </link>

    <joint name="RR_thigh_joint" type="revolute">
        <parent link="RR_hip_link"/>
        <child link="RR_thigh_link"/>
        <origin xyz="0 -0.025 0" rpy="0 0 0"/> 
        <axis xyz="0 1 0"/> 
        <limit lower="-1.5" upper="1.5" effort="10" velocity="10"/>
    </joint>

    <link name="RR_thigh_link">
        <visual>
            <geometry>
                <cylinder length="0.145" radius="0.02"/>
            </geometry>
            <origin xyz="0 0 -0.0725" rpy="0 0 0"/> 
            <material name="red"/>
        </visual>
        <collision>
            <geometry>
                <cylinder length="0.145" radius="0.02"/>
            </geometry>
            <origin xyz="0 0 -0.0725" rpy="0 0 0"/> 
        </collision>
        <inertial>
            <origin xyz="0 0 -0.0725" rpy="0 0 0"/>
            <mass value="0.075"/> 
            <inertia ixx="0.001" ixy="0.0" ixz="0.0" iyy="0.001" iyz="0.0" izz="0.001"/>
        </inertial>
    </link>

    <joint name="RR_shank_joint" type="revolute">
        <parent link="RR_thigh_link"/>
        <child link="RR_shank_link"/>
        <origin xyz="0 0 -0.145" rpy="0 0 0"/> 
        <axis xyz="0 1 0"/> 
        <limit lower="-2.5" upper="0" effort="10" velocity="10"/> 
    </joint>

    <link name="RR_shank_link">
        <visual>
            <geometry>
                <cylinder length="0.145" radius="0.02"/>
            </geometry>
            <origin xyz="0 0 -0.0725" rpy="0 0 0"/> 
            <material name="yellow"/>
        </visual>
        <collision>
            <geometry>
                <cylinder length="0.145" radius="0.02"/>
            </geometry>
            <origin xyz="0 0 -0.0725" rpy="0 0 0"/>
        </collision>
        <inertial>
            <origin xyz="0 0 -0.0725" rpy="0 0 0"/>
            <mass value="0.075"/> 
            <inertia ixx="0.001" ixy="0.0" ixz="0.0" iyy="0.001" iyz="0.0" izz="0.001"/>
        </inertial>
    </link>

    <joint name="RR_foot_joint" type="fixed"> 
        <parent link="RR_shank_link"/>
        <child link="RR_foot_link"/>
        <origin xyz="0 0 -0.145" rpy="0 0 0"/> 
    </joint>

    <link name="RR_foot_link">
        <visual>
            <geometry>
                <sphere radius="0.02"/> 
            </geometry>
            <material name="black"/>
        </visual>
        <collision>
            <geometry>
                <sphere radius="0.02"/>
            </geometry>
            <contact_coefficients kd="100.0" kp="1000.0" mu="0.8"/> 
        </collision>
        <inertial>
            <origin xyz="0 0 0" rpy="0 0 0"/>
            <mass value="0.01"/> 
            <inertia ixx="0.0001" ixy="0.0" ixz="0.0" iyy="0.0001" iyz="0.0" izz="0.0001"/>
        </inertial>
    </link>

    <joint name="RL_hip_joint" type="revolute">
        <parent link="base_link"/>
        <child link="RL_hip_link"/>
        <origin xyz="-0.195 0.145 0" rpy="0 0 0"/> 
        <axis xyz="1 0 0"/> 
        <limit lower="-0.5" upper="0.5" effort="10" velocity="10"/> 
    </joint>

    <link name="RL_hip_link">
        <visual>
            <geometry>
                <box size="0.05 0.05 0.05"/>
            </geometry>
            <material name="green"/>
        </visual>
        <collision>
            <geometry>
                <box size="0.05 0.05 0.05"/>
            </geometry>
        </collision>
        <inertial>
            <origin xyz="0 0 0" rpy="0 0 0"/>
            <mass value="0.1"/> 
            <inertia ixx="0.001" ixy="0.0" ixz="0.0" iyy="0.001" iyz="0.0" izz="0.001"/>
        </inertial>
    </link>

    <joint name="RL_thigh_joint" type="revolute">
        <parent link="RL_hip_link"/>
        <child link="RL_thigh_link"/>
        <origin xyz="0 0.025 0" rpy="0 0 0"/> 
        <axis xyz="0 1 0"/> 
        <limit lower="-1.5" upper="1.5" effort="10" velocity="10"/>
    </joint>

    <link name="RL_thigh_link">
        <visual>
            <geometry>
                <cylinder length="0.145" radius="0.02"/>
            </geometry>
            <origin xyz="0 0 -0.0725" rpy="0 0 0"/> 
            <material name="red"/>
        </visual>
        <collision>
            <geometry>
                <cylinder length="0.145" radius="0.02"/>
            </geometry>
            <origin xyz="0 0 -0.0725" rpy="0 0 0"/> 
        </collision>
        <inertial>
            <origin xyz="0 0 -0.0725" rpy="0 0 0"/>
            <mass value="0.075"/> 
            <inertia ixx="0.001" ixy="0.0" ixz="0.0" iyy="0.001" iyz="0.0" izz="0.001"/>
        </inertial>
    </link>

    <joint name="RL_shank_joint" type="revolute">
        <parent link="RL_thigh_link"/>
        <child link="RL_shank_link"/>
        <origin xyz="0 0 -0.145" rpy="0 0 0"/> 
        <axis xyz="0 1 0"/> 
        <limit lower="-2.5" upper="0" effort="10" velocity="10"/> 
    </joint>

    <link name="RL_shank_link">
        <visual>
            <geometry>
                <cylinder length="0.145" radius="0.02"/>
            </geometry>
            <origin xyz="0 0 -0.0725" rpy="0 0 0"/> 
            <material name="yellow"/>
        </visual>
        <collision>
            <geometry>
                <cylinder length="0.145" radius="0.02"/>
            </geometry>
            <origin xyz="0 0 -0.0725" rpy="0 0 0"/>
        </collision>
        <inertial>
            <origin xyz="0 0 -0.0725" rpy="0 0 0"/>
            <mass value="0.075"/> 
            <inertia ixx="0.001" ixy="0.0" ixz="0.0" iyy="0.001" iyz="0.0" izz="0.001"/>
        </inertial>
    </link>

    <joint name="RL_foot_joint" type="fixed"> 
        <parent link="RL_shank_link"/>
        <child link="RL_foot_link"/>
        <origin xyz="0 0 -0.145" rpy="0 0 0"/> 
    </joint>

    <link name="RL_foot_link">
        <visual>
            <geometry>
                <sphere radius="0.02"/> 
            </geometry>
            <material name="black"/>
        </visual>
        <collision>
            <geometry>
                <sphere radius="0.02"/>
            </geometry>
            <contact_coefficients kd="100.0" kp="1000.0" mu="0.8"/> 
        </collision>
        <inertial>
            <origin xyz="0 0 0" rpy="0 0 0"/>
            <mass value="0.01"/> 
            <inertia ixx="0.0001" ixy="0.0" ixz="0.0" iyy="0.0001" iyz="0.0" izz="0.0001"/>
        </inertial>
    </link>

    <material name="blue">
        <color rgba="0 0 1 1"/>
    </material>
    <material name="green">
        <color rgba="0 1 0 1"/>
    </material>
    <material name="red">
        <color rgba="1 0 0 1"/>
    </material>
    <material name="yellow">
        <color rgba="1 1 0 1"/>
    </material>
    <material name="black">
        <color rgba="0 0 0 1"/>
    </material>

</robot>